Workbook

Sheet README
A1: 森林益智樂園｜裝備資料匯出工作簿
A3: 用途 | B3: 這份表已升級成可直接整理為遊戲資料的版本。編輯 equipment_master 後，可從 export_ready 複製資料，或讀取 json_preview 欄位匯出。
A4: 你主要要改 | B4: equipment_master 工作表中的藍底輸入欄位
A5: 下拉選單 | B5: source / rarity / type / unlockType / effectType / status 都已設定資料驗證
A6: 直接匯出 | B6: export_ready 為遊戲端建議使用欄位；json_preview 為每列 JSON 預覽
A7: 建議流程 | B7: 先新增/修改裝備 -> 勾選 exportEnabled -> 依 sortOrder 排序 -> 匯出 export_ready 或讀取 json_preview
A8: 備註 | B8: 若要讓程式匯入，建議只讀取 export_ready 中 id 不為空的列

Sheet lookups
A1: type | B1: source | C1: rarity | D1: effectType | E1: unlockType | F1: status | G1: bool
A2: hat | B2: starter | C2: common | D2: none | E2: starter | F2: 規劃中 | G2: TRUE
A3: cloth | B3: treasure | C3: rare | D3: rewardRate | E3: drop | F3: 測試中 | G3: FALSE
A4: fullset | B4: firefly | C4: epic | D4: dropRate | E4: shop | F4: 已實作
A5: tool | B5: campfire | C5: legend | D5: extraPlayCount | E5: achievement | F5: 停用
B6: constellation | D6: revealHint | E6: reputation
B7: animals | D7: rareDropRate | E7: secret
B8: global | D8: timeBonus | E8: event
B9: secret | D9: extraMistake
D10: chestRate
D11: memoryHelp
D12: slowDown
D13: freeEntry
D14: freeStageEntry

Sheet equipment_master
A1: id | B1: name | C1: category | D1: type | E1: source | F1: rarity | G1: texture | H1: icon | I1: placeable | J1: effectType | K1: effectValue | L1: effectType2 | M1: effectValue2 | N1: rewardRate | O1: dropRate | P1: extraPlayCount | Q1: unlockType | R1: desc | S1: status | T1: notes | U1: exportEnabled | V1: sortOrder | W1: gameKey | X1: json_preview
A2: item_hat_daily_01 | B2: 小髮夾 | C2: equipment | D2: hat | E2: starter | F2: common | G2: item_hat_daily_01 | H2: item_hat_daily_01 | I2: FALSE | J2: none | K2: 0 | L2: none | M2: 0 | N2: 0 | O2: 0 | P2: 0 | Q2: starter | R2: 簡單可愛的小髮夾 | S2: 已實作 | U2: TRUE | V2: 1 | W2: starter_001 | X2: =IF($A2="","","{""id"":"""&$A2&""",""name"":"""&$B2&""",""category"":"""&$C2&""",""type"":"""&$D2&""",""source"":"""&$E2&""",""rarity"":"""&$F2&""",""texture"":"""&$G2&""",""icon"":"""&$H2&""",""placeable"":""&IF($I2,""true"",""false"")&"",""effects"":[{""type"":"""&$J2&""",""value"":""&TEXT($K2,""0.##"")&""},{""type"":"""&$L2&""",""value"":""&TEXT($M2,""0.##"")&""}],""unlockType"":"""&$Q2&""",""desc"":"""&$R2&"""}" ) -> {"id":"item_hat_daily_01","name":"小髮夾","category":"equipment","type":"hat","source":"starter","rarity":"common","texture":"item_hat_daily_01","icon":"item_hat_daily_01","placeable":"&IF($I2,"true","false")&","effects":[{"type":"none","value":"&TEXT($K2,"0.##")&"},{"type":"none","value":"&TEXT($M2,"0.##")&"}],"unlockType":"starter","desc":"簡單可愛的小髮夾"}
A3: item_cloth_daily_01 | B3: 休閒裝 | C3: equipment | D3: cloth | E3: starter | F3: common | G3: item_cloth_daily_01 | H3: item_cloth_daily_01 | I3: FALSE | J3: rewardRate | K3: 0.05 | L3: none | M3: 0 | N3: 0.05 | O3: 0 | P3: 0 | Q3: starter | R3: 舒適的日常衣服 | S3: 已實作 | U3: TRUE | V3: 2 | W3: starter_002 | X3: =IF($A3="","","{""id"":"""&$A3&""",""name"":"""&$B3&""",""category"":"""&$C3&""",""type"":"""&$D3&""",""source"":"""&$E3&""",""rarity"":"""&$F3&""",""texture"":"""&$G3&""",""icon"":"""&$H3&""",""placeable"":""&IF($I3,""true"",""false"")&"",""effects"":[{""type"":"""&$J3&""",""value"":""&TEXT($K3,""0.##"")&""},{""type"":"""&$L3&""",""value"":""&TEXT($M3,""0.##"")&""}],""unlockType"":"""&$Q3&""",""desc"":"""&$R3&"""}" ) -> {"id":"item_cloth_daily_01","name":"休閒裝","category":"equipment","type":"cloth","source":"starter","rarity":"common","texture":"item_cloth_daily_01","icon":"item_cloth_daily_01","placeable":"&IF($I3,"true","false")&","effects":[{"type":"rewardRate","value":"&TEXT($K3,"0.##")&"},{"type":"none","value":"&TEXT($M3,"0.##")&"}],"unlockType":"starter","desc":"舒適的日常衣服"}
A4: item_hat_common_tiara | B4: 小皇冠 | C4: equipment | D4: hat | E4: global | F4: rare | G4: hat_tiara | H4: icon_hat_tiara | I4: FALSE | J4: rewardRate | K4: 0.2 | L4: none | M4: 0 | N4: 0.2 | O4: 0 | P4: 0 | Q4: drop | R4: 一頂閃亮的小皇冠 | S4: 已實作 | U4: TRUE | V4: 3 | W4: global_003 | X4: =IF($A4="","","{""id"":"""&$A4&""",""name"":"""&$B4&""",""category"":"""&$C4&""",""type"":"""&$D4&""",""source"":"""&$E4&""",""rarity"":"""&$F4&""",""texture"":"""&$G4&""",""icon"":"""&$H4&""",""placeable"":""&IF($I4,""true"",""false"")&"",""effects"":[{""type"":"""&$J4&""",""value"":""&TEXT($K4,""0.##"")&""},{""type"":"""&$L4&""",""value"":""&TEXT($M4,""0.##"")&""}],""unlockType"":"""&$Q4&""",""desc"":"""&$R4&"""}" ) -> {"id":"item_hat_common_tiara","name":"小皇冠","category":"equipment","type":"hat","source":"global","rarity":"rare","texture":"hat_tiara","icon":"icon_hat_tiara","placeable":"&IF($I4,"true","false")&","effects":[{"type":"rewardRate","value":"&TEXT($K4,"0.##")&"},{"type":"none","value":"&TEXT($M4,"0.##")&"}],"unlockType":"drop","desc":"一頂閃亮的小皇冠"}
A5: item_cloth_common_fairy | B5: 小仙子洋裝 | C5: equipment | D5: cloth | E5: firefly | F5: rare | G5: cloth_fairy | H5: icon_cloth_fairy | I5: FALSE | J5: dropRate | K5: 0.15 | L5: none | M5: 0 | N5: 0 | O5: 0.15 | P5: 0 | Q5: drop | R5: 輕盈可愛的小仙子洋裝 | S5: 已實作 | U5: TRUE | V5: 4 | W5: firefly_004 | X5: =IF($A5="","","{""id"":"""&$A5&""",""name"":"""&$B5&""",""category"":"""&$C5&""",""type"":"""&$D5&""",""source"":"""&$E5&""",""rarity"":"""&$F5&""",""texture"":"""&$G5&""",""icon"":"""&$H5&""",""placeable"":""&IF($I5,""true"",""false"")&"",""effects"":[{""type"":"""&$J5&""",""value"":""&TEXT($K5,""0.##"")&""},{""type"":"""&$L5&""",""value"":""&TEXT($M5,""0.##"")&""}],""unlockType"":"""&$Q5&""",""desc"":"""&$R5&"""}" ) -> {"id":"item_cloth_common_fairy","name":"小仙子洋裝","category":"equipment","type":"cloth","source":"firefly","rarity":"rare","texture":"cloth_fairy","icon":"icon_cloth_fairy","placeable":"&IF($I5,"true","false")&","effects":[{"type":"dropRate","value":"&TEXT($K5,"0.##")&"},{"type":"none","value":"&TEXT($M5,"0.##")&"}],"unlockType":"drop","desc":"輕盈可愛的小仙子洋裝"}
A6: item_fullset_pink_home_01 | B6: 粉色居家服 | C6: equipment | D6: fullset | E6: starter | F6: common | G6: fullset_pink_home_01 | H6: icon_fullset_pink_home_01 | I6: FALSE | J6: rewardRate | K6: 0.1 | L6: dropRate | M6: 0.05 | N6: 0.1 | O6: 0.05 | P6: 0 | Q6: starter | R6: 舒服又可愛的粉色居家服 | S6: 已實作 | U6: TRUE | V6: 5 | W6: starter_005 | X6: =IF($A6="","","{""id"":"""&$A6&""",""name"":"""&$B6&""",""category"":"""&$C6&""",""type"":"""&$D6&""",""source"":"""&$E6&""",""rarity"":"""&$F6&""",""texture"":"""&$G6&""",""icon"":"""&$H6&""",""placeable"":""&IF($I6,""true"",""false"")&"",""effects"":[{""type"":"""&$J6&""",""value"":""&TEXT($K6,""0.##"")&""},{""type"":"""&$L6&""",""value"":""&TEXT($M6,""0.##"")&""}],""unlockType"":"""&$Q6&""",""desc"":"""&$R6&"""}" ) -> {"id":"item_fullset_pink_home_01","name":"粉色居家服","category":"equipment","type":"fullset","source":"starter","rarity":"common","texture":"fullset_pink_home_01","icon":"icon_fullset_pink_home_01","placeable":"&IF($I6,"true","false")&","effects":[{"type":"rewardRate","value":"&TEXT($K6,"0.##")&"},{"type":"dropRate","value":"&TEXT($M6,"0.##")&"}],"unlockType":"starter","desc":"舒服又可愛的粉色居家服"}
A7: item_hat_explore_01 | B7: 探險遮陽帽 | C7: equipment | D7: hat | E7: treasure | F7: rare | G7: hat_explorer | H7: icon_hat_explorer | I7: FALSE | J7: extraPlayCount | K7: 1 | L7: none | M7: 0 | N7: 0 | O7: 0 | P7: 1 | Q7: drop | R7: 探險時能多一次嘗試機會 | S7: 測試中 | U7: TRUE | V7: 6 | W7: treasure_006 | X7: =IF($A7="","","{""id"":"""&$A7&""",""name"":"""&$B7&""",""category"":"""&$C7&""",""type"":"""&$D7&""",""source"":"""&$E7&""",""rarity"":"""&$F7&""",""texture"":"""&$G7&""",""icon"":"""&$H7&""",""placeable"":""&IF($I7,""true"",""false"")&"",""effects"":[{""type"":"""&$J7&""",""value"":""&TEXT($K7,""0.##"")&""},{""type"":"""&$L7&""",""value"":""&TEXT($M7,""0.##"")&""}],""unlockType"":"""&$Q7&""",""desc"":"""&$R7&"""}" ) -> {"id":"item_hat_explore_01","name":"探險遮陽帽","category":"equipment","type":"hat","source":"treasure","rarity":"rare","texture":"hat_explorer","icon":"icon_hat_explorer","placeable":"&IF($I7,"true","false")&","effects":[{"type":"extraPlayCount","value":"&TEXT($K7,"0.##")&"},{"type":"none","value":"&TEXT($M7,"0.##")&"}],"unlockType":"drop","desc":"探險時能多一次嘗試機會"}
A8: item_cloth_explore_01 | B8: 多口袋背心 | C8: equipment | D8: cloth | E8: treasure | F8: rare | G8: cloth_explorer | H8: icon_cloth_explorer | I8: FALSE | J8: dropRate | K8: 0.1 | L8: none | M8: 0 | N8: 0 | O8: 0.1 | P8: 0 | Q8: drop | R8: 身上掛滿各種探險口袋 | S8: 測試中 | U8: TRUE | V8: 7 | W8: treasure_007 | X8: =IF($A8="","","{""id"":"""&$A8&""",""name"":"""&$B8&""",""category"":"""&$C8&""",""type"":"""&$D8&""",""source"":"""&$E8&""",""rarity"":"""&$F8&""",""texture"":"""&$G8&""",""icon"":"""&$H8&""",""placeable"":""&IF($I8,""true"",""false"")&"",""effects"":[{""type"":"""&$J8&""",""value"":""&TEXT($K8,""0.##"")&""},{""type"":"""&$L8&""",""value"":""&TEXT($M8,""0.##"")&""}],""unlockType"":"""&$Q8&""",""desc"":"""&$R8&"""}" ) -> {"id":"item_cloth_explore_01","name":"多口袋背心","category":"equipment","type":"cloth","source":"treasure","rarity":"rare","texture":"cloth_explorer","icon":"icon_cloth_explorer","placeable":"&IF($I8,"true","false")&","effects":[{"type":"dropRate","value":"&TEXT($K8,"0.##")&"},{"type":"none","value":"&TEXT($M8,"0.##")&"}],"unlockType":"drop","desc":"身上掛滿各種探險口袋"}
A9: item_fullset_explore_01 | B9: 野外小偵查 | C9: equipment | D9: fullset | E9: treasure | F9: rare | G9: fullset_explorer | H9: icon_fullset_explorer | I9: FALSE | J9: revealHint | K9: 1 | L9: none | M9: 0 | N9: 0 | O9: 0 | P9: 0 | Q9: drop | R9: 一件充滿探險味道的衣服 | S9: 測試中 | U9: TRUE | V9: 8 | W9: treasure_008 | X9: =IF($A9="","","{""id"":"""&$A9&""",""name"":"""&$B9&""",""category"":"""&$C9&""",""type"":"""&$D9&""",""source"":"""&$E9&""",""rarity"":"""&$F9&""",""texture"":"""&$G9&""",""icon"":"""&$H9&""",""placeable"":""&IF($I9,""true"",""false"")&"",""effects"":[{""type"":"""&$J9&""",""value"":""&TEXT($K9,""0.##"")&""},{""type"":"""&$L9&""",""value"":""&TEXT($M9,""0.##"")&""}],""unlockType"":"""&$Q9&""",""desc"":"""&$R9&"""}" ) -> {"id":"item_fullset_explore_01","name":"野外小偵查","category":"equipment","type":"fullset","source":"treasure","rarity":"rare","texture":"fullset_explorer","icon":"icon_fullset_explorer","placeable":"&IF($I9,"true","false")&","effects":[{"type":"revealHint","value":"&TEXT($K9,"0.##")&"},{"type":"none","value":"&TEXT($M9,"0.##")&"}],"unlockType":"drop","desc":"一件充滿探險味道的衣服"}
A10: item_tool_explore_01 | B10: 高能放大鏡 | C10: tool | D10: tool | E10: treasure | F10: rare | G10: tool_magnifier | H10: icon_magnifier | I10: FALSE | J10: rareDropRate | K10: 0.05 | L10: none | M10: 0 | N10: 0 | O10: 0 | P10: 0 | Q10: drop | R10: 讓寶藏的細節變得更明顯 | S10: 測試中 | U10: TRUE | V10: 9 | W10: treasure_009 | X10: =IF($A10="","","{""id"":"""&$A10&""",""name"":"""&$B10&""",""category"":"""&$C10&""",""type"":"""&$D10&""",""source"":"""&$E10&""",""rarity"":"""&$F10&""",""texture"":"""&$G10&""",""icon"":"""&$H10&""",""placeable"":""&IF($I10,""true"",""false"")&"",""effects"":[{""type"":"""&$J10&""",""value"":""&TEXT($K10,""0.##"")&""},{""type"":"""&$L10&""",""value"":""&TEXT($M10,""0.##"")&""}],""unlockType"":"""&$Q10&""",""desc"":"""&$R10&"""}" ) -> {"id":"item_tool_explore_01","name":"高能放大鏡","category":"tool","type":"tool","source":"treasure","rarity":"rare","texture":"tool_magnifier","icon":"icon_magnifier","placeable":"&IF($I10,"true","false")&","effects":[{"type":"rareDropRate","value":"&TEXT($K10,"0.##")&"},{"type":"none","value":"&TEXT($M10,"0.##")&"}],"unlockType":"drop","desc":"讓寶藏的細節變得更明顯"}
A11: item_hat_firefly_01 | B11: 螢光小帽 | C11: equipment | D11: hat | E11: firefly | F11: rare | G11: hat_firefly | H11: icon_hat_firefly | I11: FALSE | J11: timeBonus | K11: 3 | L11: none | M11: 0 | N11: 0 | O11: 0 | P11: 0 | Q11: drop | R11: 夜晚的螢光會停留得更久 | S11: 測試中 | U11: TRUE | V11: 10 | W11: firefly_010 | X11: =IF($A11="","","{""id"":"""&$A11&""",""name"":"""&$B11&""",""category"":"""&$C11&""",""type"":"""&$D11&""",""source"":"""&$E11&""",""rarity"":"""&$F11&""",""texture"":"""&$G11&""",""icon"":"""&$H11&""",""placeable"":""&IF($I11,""true"",""false"")&"",""effects"":[{""type"":"""&$J11&""",""value"":""&TEXT($K11,""0.##"")&""},{""type"":"""&$L11&""",""value"":""&TEXT($M11,""0.##"")&""}],""unlockType"":"""&$Q11&""",""desc"":"""&$R11&"""}" ) -> {"id":"item_hat_firefly_01","name":"螢光小帽","category":"equipment","type":"hat","source":"firefly","rarity":"rare","texture":"hat_firefly","icon":"icon_hat_firefly","placeable":"&IF($I11,"true","false")&","effects":[{"type":"timeBonus","value":"&TEXT($K11,"0.##")&"},{"type":"none","value":"&TEXT($M11,"0.##")&"}],"unlockType":"drop","desc":"夜晚的螢光會停留得更久"}
A12: item_cloth_firefly_01 | B12: 發光小背心 | C12: equipment | D12: cloth | E12: firefly | F12: rare | G12: cloth_firefly | H12: icon_cloth_firefly | I12: FALSE | J12: rewardRate | K12: 0.15 | L12: none | M12: 0 | N12: 0.15 | O12: 0 | P12: 0 | Q12: drop | R12: 微微發光的小背心 | S12: 測試中 | U12: TRUE | V12: 11 | W12: firefly_011 | X12: =IF($A12="","","{""id"":"""&$A12&""",""name"":"""&$B12&""",""category"":"""&$C12&""",""type"":"""&$D12&""",""source"":"""&$E12&""",""rarity"":"""&$F12&""",""texture"":"""&$G12&""",""icon"":"""&$H12&""",""placeable"":""&IF($I12,""true"",""false"")&"",""effects"":[{""type"":"""&$J12&""",""value"":""&TEXT($K12,""0.##"")&""},{""type"":"""&$L12&""",""value"":""&TEXT($M12,""0.##"")&""}],""unlockType"":"""&$Q12&""",""desc"":"""&$R12&"""}" ) -> {"id":"item_cloth_firefly_01","name":"發光小背心","category":"equipment","type":"cloth","source":"firefly","rarity":"rare","texture":"cloth_firefly","icon":"icon_cloth_firefly","placeable":"&IF($I12,"true","false")&","effects":[{"type":"rewardRate","value":"&TEXT($K12,"0.##")&"},{"type":"none","value":"&TEXT($M12,"0.##")&"}],"unlockType":"drop","desc":"微微發光的小背心"}
A13: item_fullset_firefly_01 | B13: 森林精靈服 | C13: equipment | D13: fullset | E13: firefly | F13: rare | G13: fullset_firefly | H13: icon_fullset_firefly | I13: FALSE | J13: extraMistake | K13: 1 | L13: none | M13: 0 | N13: 0 | O13: 0 | P13: 0 | Q13: drop | R13: 帶有森林魔法的精靈服 | S13: 測試中 | U13: TRUE | V13: 12 | W13: firefly_012 | X13: =IF($A13="","","{""id"":"""&$A13&""",""name"":"""&$B13&""",""category"":"""&$C13&""",""type"":"""&$D13&""",""source"":"""&$E13&""",""rarity"":"""&$F13&""",""texture"":"""&$G13&""",""icon"":"""&$H13&""",""placeable"":""&IF($I13,""true"",""false"")&"",""effects"":[{""type"":"""&$J13&""",""value"":""&TEXT($K13,""0.##"")&""},{""type"":"""&$L13&""",""value"":""&TEXT($M13,""0.##"")&""}],""unlockType"":"""&$Q13&""",""desc"":"""&$R13&"""}" ) -> {"id":"item_fullset_firefly_01","name":"森林精靈服","category":"equipment","type":"fullset","source":"firefly","rarity":"rare","texture":"fullset_firefly","icon":"icon_fullset_firefly","placeable":"&IF($I13,"true","false")&","effects":[{"type":"extraMistake","value":"&TEXT($K13,"0.##")&"},{"type":"none","value":"&TEXT($M13,"0.##")&"}],"unlockType":"drop","desc":"帶有森林魔法的精靈服"}
A14: item_tool_firefly_01 | B14: 許願玻璃瓶 | C14: tool | D14: tool | E14: firefly | F14: rare | G14: tool_firefly_jar | H14: icon_firefly_jar | I14: FALSE | J14: chestRate | K14: 0.1 | L14: none | M14: 0 | N14: 0 | O14: 0 | P14: 0 | Q14: drop | R14: 裝滿螢火蟲的玻璃瓶 | S14: 測試中 | U14: TRUE | V14: 13 | W14: firefly_013 | X14: =IF($A14="","","{""id"":"""&$A14&""",""name"":"""&$B14&""",""category"":"""&$C14&""",""type"":"""&$D14&""",""source"":"""&$E14&""",""rarity"":"""&$F14&""",""texture"":"""&$G14&""",""icon"":"""&$H14&""",""placeable"":""&IF($I14,""true"",""false"")&"",""effects"":[{""type"":"""&$J14&""",""value"":""&TEXT($K14,""0.##"")&""},{""type"":"""&$L14&""",""value"":""&TEXT($M14,""0.##"")&""}],""unlockType"":"""&$Q14&""",""desc"":"""&$R14&"""}" ) -> {"id":"item_tool_firefly_01","name":"許願玻璃瓶","category":"tool","type":"tool","source":"firefly","rarity":"rare","texture":"tool_firefly_jar","icon":"icon_firefly_jar","placeable":"&IF($I14,"true","false")&","effects":[{"type":"chestRate","value":"&TEXT($K14,"0.##")&"},{"type":"none","value":"&TEXT($M14,"0.##")&"}],"unlockType":"drop","desc":"裝滿螢火蟲的玻璃瓶"}
A15: item_hat_campfire_01 | B15: 火焰廚師帽 | C15: equipment | D15: hat | E15: campfire | F15: rare | G15: hat_cook | H15: icon_hat_cook | I15: FALSE | J15: timeBonus | K15: 3 | L15: none | M15: 0 | N15: 0 | O15: 0 | P15: 0 | Q15: drop | R15: 營火料理專用廚師帽 | S15: 測試中 | U15: TRUE | V15: 14 | W15: campfire_014 | X15: =IF($A15="","","{""id"":"""&$A15&""",""name"":"""&$B15&""",""category"":"""&$C15&""",""type"":"""&$D15&""",""source"":"""&$E15&""",""rarity"":"""&$F15&""",""texture"":"""&$G15&""",""icon"":"""&$H15&""",""placeable"":""&IF($I15,""true"",""false"")&"",""effects"":[{""type"":"""&$J15&""",""value"":""&TEXT($K15,""0.##"")&""},{""type"":"""&$L15&""",""value"":""&TEXT($M15,""0.##"")&""}],""unlockType"":"""&$Q15&""",""desc"":"""&$R15&"""}" ) -> {"id":"item_hat_campfire_01","name":"火焰廚師帽","category":"equipment","type":"hat","source":"campfire","rarity":"rare","texture":"hat_cook","icon":"icon_hat_cook","placeable":"&IF($I15,"true","false")&","effects":[{"type":"timeBonus","value":"&TEXT($K15,"0.##")&"},{"type":"none","value":"&TEXT($M15,"0.##")&"}],"unlockType":"drop","desc":"營火料理專用廚師帽"}
A16: item_cloth_campfire_01 | B16: 美味圍裙 | C16: equipment | D16: cloth | E16: campfire | F16: rare | G16: cloth_cook | H16: icon_cloth_cook | I16: FALSE | J16: rewardRate | K16: 0.2 | L16: none | M16: 0 | N16: 0.2 | O16: 0 | P16: 0 | Q16: drop | R16: 料理時的必備圍裙 | S16: 測試中 | U16: TRUE | V16: 15 | W16: campfire_015 | X16: =IF($A16="","","{""id"":"""&$A16&""",""name"":"""&$B16&""",""category"":"""&$C16&""",""type"":"""&$D16&""",""source"":"""&$E16&""",""rarity"":"""&$F16&""",""texture"":"""&$G16&""",""icon"":"""&$H16&""",""placeable"":""&IF($I16,""true"",""false"")&"",""effects"":[{""type"":"""&$J16&""",""value"":""&TEXT($K16,""0.##"")&""},{""type"":"""&$L16&""",""value"":""&TEXT($M16,""0.##"")&""}],""unlockType"":"""&$Q16&""",""desc"":"""&$R16&"""}" ) -> {"id":"item_cloth_campfire_01","name":"美味圍裙","category":"equipment","type":"cloth","source":"campfire","rarity":"rare","texture":"cloth_cook","icon":"icon_cloth_cook","placeable":"&IF($I16,"true","false")&","effects":[{"type":"rewardRate","value":"&TEXT($K16,"0.##")&"},{"type":"none","value":"&TEXT($M16,"0.##")&"}],"unlockType":"drop","desc":"料理時的必備圍裙"}
A17: item_fullset_campfire_01 | B17: 三星大廚袍 | C17: equipment | D17: fullset | E17: campfire | F17: rare | G17: fullset_cook | H17: icon_fullset_cook | I17: FALSE | J17: extraMistake | K17: 1 | L17: none | M17: 0 | N17: 0 | O17: 0 | P17: 0 | Q17: drop | R17: 穿上就像營火料理大師 | S17: 測試中 | U17: TRUE | V17: 16 | W17: campfire_016 | X17: =IF($A17="","","{""id"":"""&$A17&""",""name"":"""&$B17&""",""category"":"""&$C17&""",""type"":"""&$D17&""",""source"":"""&$E17&""",""rarity"":"""&$F17&""",""texture"":"""&$G17&""",""icon"":"""&$H17&""",""placeable"":""&IF($I17,""true"",""false"")&"",""effects"":[{""type"":"""&$J17&""",""value"":""&TEXT($K17,""0.##"")&""},{""type"":"""&$L17&""",""value"":""&TEXT($M17,""0.##"")&""}],""unlockType"":"""&$Q17&""",""desc"":"""&$R17&"""}" ) -> {"id":"item_fullset_campfire_01","name":"三星大廚袍","category":"equipment","type":"fullset","source":"campfire","rarity":"rare","texture":"fullset_cook","icon":"icon_fullset_cook","placeable":"&IF($I17,"true","false")&","effects":[{"type":"extraMistake","value":"&TEXT($K17,"0.##")&"},{"type":"none","value":"&TEXT($M17,"0.##")&"}],"unlockType":"drop","desc":"穿上就像營火料理大師"}
A18: item_tool_campfire_01 | B18: 黃金烤肉夾 | C18: tool | D18: tool | E18: campfire | F18: rare | G18: tool_tongs | H18: icon_tongs | I18: FALSE | J18: chestRate | K18: 0.1 | L18: none | M18: 0 | N18: 0 | O18: 0 | P18: 0 | Q18: drop | R18: 傳說中不會烤焦食物的夾子 | S18: 測試中 | U18: TRUE | V18: 17 | W18: campfire_017 | X18: =IF($A18="","","{""id"":"""&$A18&""",""name"":"""&$B18&""",""category"":"""&$C18&""",""type"":"""&$D18&""",""source"":"""&$E18&""",""rarity"":"""&$F18&""",""texture"":"""&$G18&""",""icon"":"""&$H18&""",""placeable"":""&IF($I18,""true"",""false"")&"",""effects"":[{""type"":"""&$J18&""",""value"":""&TEXT($K18,""0.##"")&""},{""type"":"""&$L18&""",""value"":""&TEXT($M18,""0.##"")&""}],""unlockType"":"""&$Q18&""",""desc"":"""&$R18&"""}" ) -> {"id":"item_tool_campfire_01","name":"黃金烤肉夾","category":"tool","type":"tool","source":"campfire","rarity":"rare","texture":"tool_tongs","icon":"icon_tongs","placeable":"&IF($I18,"true","false")&","effects":[{"type":"chestRate","value":"&TEXT($K18,"0.##")&"},{"type":"none","value":"&TEXT($M18,"0.##")&"}],"unlockType":"drop","desc":"傳說中不會烤焦食物的夾子"}
A19: item_hat_constellation_01 | B19: 星辰魔法帽 | C19: equipment | D19: hat | E19: constellation | F19: rare | G19: hat_constellation | H19: icon_hat_constellation | I19: FALSE | J19: memoryHelp | K19: 1 | L19: none | M19: 0 | N19: 0 | O19: 0 | P19: 0 | Q19: drop | R19: 讓星星連線變得更清楚 | S19: 測試中 | U19: TRUE | V19: 18 | W19: constellation_018 | X19: =IF($A19="","","{""id"":"""&$A19&""",""name"":"""&$B19&""",""category"":"""&$C19&""",""type"":"""&$D19&""",""source"":"""&$E19&""",""rarity"":"""&$F19&""",""texture"":"""&$G19&""",""icon"":"""&$H19&""",""placeable"":""&IF($I19,""true"",""false"")&"",""effects"":[{""type"":"""&$J19&""",""value"":""&TEXT($K19,""0.##"")&""},{""type"":"""&$L19&""",""value"":""&TEXT($M19,""0.##"")&""}],""unlockType"":"""&$Q19&""",""desc"":"""&$R19&"""}" ) -> {"id":"item_hat_constellation_01","name":"星辰魔法帽","category":"equipment","type":"hat","source":"constellation","rarity":"rare","texture":"hat_constellation","icon":"icon_hat_constellation","placeable":"&IF($I19,"true","false")&","effects":[{"type":"memoryHelp","value":"&TEXT($K19,"0.##")&"},{"type":"none","value":"&TEXT($M19,"0.##")&"}],"unlockType":"drop","desc":"讓星星連線變得更清楚"}
A20: item_cloth_constellation_01 | B20: 銀河特工衣 | C20: equipment | D20: cloth | E20: constellation | F20: rare | G20: cloth_constellation | H20: icon_cloth_constellation | I20: FALSE | J20: rewardRate | K20: 0.15 | L20: none | M20: 0 | N20: 0.15 | O20: 0 | P20: 0 | Q20: drop | R20: 像銀河巡航員一樣帥氣 | S20: 測試中 | U20: TRUE | V20: 19 | W20: constellation_019 | X20: =IF($A20="","","{""id"":"""&$A20&""",""name"":"""&$B20&""",""category"":"""&$C20&""",""type"":"""&$D20&""",""source"":"""&$E20&""",""rarity"":"""&$F20&""",""texture"":"""&$G20&""",""icon"":"""&$H20&""",""placeable"":""&IF($I20,""true"",""false"")&"",""effects"":[{""type"":"""&$J20&""",""value"":""&TEXT($K20,""0.##"")&""},{""type"":"""&$L20&""",""value"":""&TEXT($M20,""0.##"")&""}],""unlockType"":"""&$Q20&""",""desc"":"""&$R20&"""}" ) -> {"id":"item_cloth_constellation_01","name":"銀河特工衣","category":"equipment","type":"cloth","source":"constellation","rarity":"rare","texture":"cloth_constellation","icon":"icon_cloth_constellation","placeable":"&IF($I20,"true","false")&","effects":[{"type":"rewardRate","value":"&TEXT($K20,"0.##")&"},{"type":"none","value":"&TEXT($M20,"0.##")&"}],"unlockType":"drop","desc":"像銀河巡航員一樣帥氣"}
A21: item_fullset_constellation_01 | B21: 小小太空人 | C21: equipment | D21: fullset | E21: constellation | F21: rare | G21: fullset_constellation | H21: icon_fullset_constellation | I21: FALSE | J21: revealHint | K21: 1 | L21: none | M21: 0 | N21: 0 | O21: 0 | P21: 0 | Q21: drop | R21: 穿上後像在夜空裡旅行 | S21: 測試中 | U21: TRUE | V21: 20 | W21: constellation_020 | X21: =IF($A21="","","{""id"":"""&$A21&""",""name"":"""&$B21&""",""category"":"""&$C21&""",""type"":"""&$D21&""",""source"":"""&$E21&""",""rarity"":"""&$F21&""",""texture"":"""&$G21&""",""icon"":"""&$H21&""",""placeable"":""&IF($I21,""true"",""false"")&"",""effects"":[{""type"":"""&$J21&""",""value"":""&TEXT($K21,""0.##"")&""},{""type"":"""&$L21&""",""value"":""&TEXT($M21,""0.##"")&""}],""unlockType"":"""&$Q21&""",""desc"":"""&$R21&"""}" ) -> {"id":"item_fullset_constellation_01","name":"小小太空人","category":"equipment","type":"fullset","source":"constellation","rarity":"rare","texture":"fullset_constellation","icon":"icon_fullset_constellation","placeable":"&IF($I21,"true","false")&","effects":[{"type":"revealHint","value":"&TEXT($K21,"0.##")&"},{"type":"none","value":"&TEXT($M21,"0.##")&"}],"unlockType":"drop","desc":"穿上後像在夜空裡旅行"}
A22: item_tool_constellation_01 | B22: 星光連線筆 | C22: tool | D22: tool | E22: constellation | F22: rare | G22: tool_star_pen | H22: icon_star_pen | I22: FALSE | J22: timeBonus | K22: 3 | L22: none | M22: 0 | N22: 0 | O22: 0 | P22: 0 | Q22: drop | R22: 幫助你畫出完整的星座軌跡 | S22: 測試中 | U22: TRUE | V22: 21 | W22: constellation_021 | X22: =IF($A22="","","{""id"":"""&$A22&""",""name"":"""&$B22&""",""category"":"""&$C22&""",""type"":"""&$D22&""",""source"":"""&$E22&""",""rarity"":"""&$F22&""",""texture"":"""&$G22&""",""icon"":"""&$H22&""",""placeable"":""&IF($I22,""true"",""false"")&"",""effects"":[{""type"":"""&$J22&""",""value"":""&TEXT($K22,""0.##"")&""},{""type"":"""&$L22&""",""value"":""&TEXT($M22,""0.##"")&""}],""unlockType"":"""&$Q22&""",""desc"":"""&$R22&"""}" ) -> {"id":"item_tool_constellation_01","name":"星光連線筆","category":"tool","type":"tool","source":"constellation","rarity":"rare","texture":"tool_star_pen","icon":"icon_star_pen","placeable":"&IF($I22,"true","false")&","effects":[{"type":"timeBonus","value":"&TEXT($K22,"0.##")&"},{"type":"none","value":"&TEXT($M22,"0.##")&"}],"unlockType":"drop","desc":"幫助你畫出完整的星座軌跡"}
A23: item_hat_animals_01 | B23: 動物耳朵帽 | C23: equipment | D23: hat | E23: animals | F23: rare | G23: hat_animals | H23: icon_hat_animals | I23: FALSE | J23: revealHint | K23: 1 | L23: none | M23: 0 | N23: 0 | O23: 0 | P23: 0 | Q23: drop | R23: 可愛的動物耳朵帽 | S23: 測試中 | U23: TRUE | V23: 22 | W23: animals_022 | X23: =IF($A23="","","{""id"":"""&$A23&""",""name"":"""&$B23&""",""category"":"""&$C23&""",""type"":"""&$D23&""",""source"":"""&$E23&""",""rarity"":"""&$F23&""",""texture"":"""&$G23&""",""icon"":"""&$H23&""",""placeable"":""&IF($I23,""true"",""false"")&"",""effects"":[{""type"":"""&$J23&""",""value"":""&TEXT($K23,""0.##"")&""},{""type"":"""&$L23&""",""value"":""&TEXT($M23,""0.##"")&""}],""unlockType"":"""&$Q23&""",""desc"":"""&$R23&"""}" ) -> {"id":"item_hat_animals_01","name":"動物耳朵帽","category":"equipment","type":"hat","source":"animals","rarity":"rare","texture":"hat_animals","icon":"icon_hat_animals","placeable":"&IF($I23,"true","false")&","effects":[{"type":"revealHint","value":"&TEXT($K23,"0.##")&"},{"type":"none","value":"&TEXT($M23,"0.##")&"}],"unlockType":"drop","desc":"可愛的動物耳朵帽"}
A24: item_cloth_animals_01 | B24: 排隊小隊長服 | C24: equipment | D24: cloth | E24: animals | F24: rare | G24: cloth_animals | H24: icon_cloth_animals | I24: FALSE | J24: slowDown | K24: 0.15 | L24: none | M24: 0 | N24: 0 | O24: 0 | P24: 0 | Q24: drop | R24: 讓動物排隊節奏慢一些 | S24: 測試中 | U24: TRUE | V24: 23 | W24: animals_023 | X24: =IF($A24="","","{""id"":"""&$A24&""",""name"":"""&$B24&""",""category"":"""&$C24&""",""type"":"""&$D24&""",""source"":"""&$E24&""",""rarity"":"""&$F24&""",""texture"":"""&$G24&""",""icon"":"""&$H24&""",""placeable"":""&IF($I24,""true"",""false"")&"",""effects"":[{""type"":"""&$J24&""",""value"":""&TEXT($K24,""0.##"")&""},{""type"":"""&$L24&""",""value"":""&TEXT($M24,""0.##"")&""}],""unlockType"":"""&$Q24&""",""desc"":"""&$R24&"""}" ) -> {"id":"item_cloth_animals_01","name":"排隊小隊長服","category":"equipment","type":"cloth","source":"animals","rarity":"rare","texture":"cloth_animals","icon":"icon_cloth_animals","placeable":"&IF($I24,"true","false")&","effects":[{"type":"slowDown","value":"&TEXT($K24,"0.##")&"},{"type":"none","value":"&TEXT($M24,"0.##")&"}],"unlockType":"drop","desc":"讓動物排隊節奏慢一些"}
A25: item_fullset_animals_01 | B25: 毛茸茸熊裝 | C25: equipment | D25: fullset | E25: animals | F25: rare | G25: fullset_animals | H25: icon_fullset_animals | I25: FALSE | J25: extraMistake | K25: 1 | L25: none | M25: 0 | N25: 0 | O25: 0 | P25: 0 | Q25: drop | R25: 毛茸茸的熊熊套裝 | S25: 測試中 | U25: TRUE | V25: 24 | W25: animals_024 | X25: =IF($A25="","","{""id"":"""&$A25&""",""name"":"""&$B25&""",""category"":"""&$C25&""",""type"":"""&$D25&""",""source"":"""&$E25&""",""rarity"":"""&$F25&""",""texture"":"""&$G25&""",""icon"":"""&$H25&""",""placeable"":""&IF($I25,""true"",""false"")&"",""effects"":[{""type"":"""&$J25&""",""value"":""&TEXT($K25,""0.##"")&""},{""type"":"""&$L25&""",""value"":""&TEXT($M25,""0.##"")&""}],""unlockType"":"""&$Q25&""",""desc"":"""&$R25&"""}" ) -> {"id":"item_fullset_animals_01","name":"毛茸茸熊裝","category":"equipment","type":"fullset","source":"animals","rarity":"rare","texture":"fullset_animals","icon":"icon_fullset_animals","placeable":"&IF($I25,"true","false")&","effects":[{"type":"extraMistake","value":"&TEXT($K25,"0.##")&"},{"type":"none","value":"&TEXT($M25,"0.##")&"}],"unlockType":"drop","desc":"毛茸茸的熊熊套裝"}
A26: item_tool_animals_01 | B26: 森林指揮棒 | C26: tool | D26: tool | E26: animals | F26: rare | G26: tool_baton | H26: icon_baton | I26: FALSE | J26: rewardRate | K26: 0.15 | L26: none | M26: 0 | N26: 0.15 | O26: 0 | P26: 0 | Q26: drop | R26: 揮一揮，動物們就排好隊 | S26: 測試中 | U26: TRUE | V26: 25 | W26: animals_025 | X26: =IF($A26="","","{""id"":"""&$A26&""",""name"":"""&$B26&""",""category"":"""&$C26&""",""type"":"""&$D26&""",""source"":"""&$E26&""",""rarity"":"""&$F26&""",""texture"":"""&$G26&""",""icon"":"""&$H26&""",""placeable"":""&IF($I26,""true"",""false"")&"",""effects"":[{""type"":"""&$J26&""",""value"":""&TEXT($K26,""0.##"")&""},{""type"":"""&$L26&""",""value"":""&TEXT($M26,""0.##"")&""}],""unlockType"":"""&$Q26&""",""desc"":"""&$R26&"""}" ) -> {"id":"item_tool_animals_01","name":"森林指揮棒","category":"tool","type":"tool","source":"animals","rarity":"rare","texture":"tool_baton","icon":"icon_baton","placeable":"&IF($I26,"true","false")&","effects":[{"type":"rewardRate","value":"&TEXT($K26,"0.##")&"},{"type":"none","value":"&TEXT($M26,"0.##")&"}],"unlockType":"drop","desc":"揮一揮，動物們就排好隊"}
A27: item_hat_global_01 | B27: 紅色運動帽 | C27: equipment | D27: hat | E27: global | F27: common | G27: hat_red_sport | H27: icon_hat_red_sport | I27: FALSE | J27: extraPlayCount | K27: 1 | L27: none | M27: 0 | N27: 0 | O27: 0 | P27: 1 | Q27: shop | R27: 運動風的紅色帽子 | S27: 測試中 | U27: TRUE | V27: 26 | W27: global_026 | X27: =IF($A27="","","{""id"":"""&$A27&""",""name"":"""&$B27&""",""category"":"""&$C27&""",""type"":"""&$D27&""",""source"":"""&$E27&""",""rarity"":"""&$F27&""",""texture"":"""&$G27&""",""icon"":"""&$H27&""",""placeable"":""&IF($I27,""true"",""false"")&"",""effects"":[{""type"":"""&$J27&""",""value"":""&TEXT($K27,""0.##"")&""},{""type"":"""&$L27&""",""value"":""&TEXT($M27,""0.##"")&""}],""unlockType"":"""&$Q27&""",""desc"":"""&$R27&"""}" ) -> {"id":"item_hat_global_01","name":"紅色運動帽","category":"equipment","type":"hat","source":"global","rarity":"common","texture":"hat_red_sport","icon":"icon_hat_red_sport","placeable":"&IF($I27,"true","false")&","effects":[{"type":"extraPlayCount","value":"&TEXT($K27,"0.##")&"},{"type":"none","value":"&TEXT($M27,"0.##")&"}],"unlockType":"shop","desc":"運動風的紅色帽子"}
A28: item_cloth_global_01 | B28: 紅色運動服 | C28: equipment | D28: cloth | E28: global | F28: common | G28: cloth_red_sport | H28: icon_cloth_red_sport | I28: FALSE | J28: rewardRate | K28: 0.1 | L28: none | M28: 0 | N28: 0.1 | O28: 0 | P28: 0 | Q28: shop | R28: 大人帶幼兒園的運動服 | S28: 測試中 | U28: TRUE | V28: 27 | W28: global_027 | X28: =IF($A28="","","{""id"":"""&$A28&""",""name"":"""&$B28&""",""category"":"""&$C28&""",""type"":"""&$D28&""",""source"":"""&$E28&""",""rarity"":"""&$F28&""",""texture"":"""&$G28&""",""icon"":"""&$H28&""",""placeable"":""&IF($I28,""true"",""false"")&"",""effects"":[{""type"":"""&$J28&""",""value"":""&TEXT($K28,""0.##"")&""},{""type"":"""&$L28&""",""value"":""&TEXT($M28,""0.##"")&""}],""unlockType"":"""&$Q28&""",""desc"":"""&$R28&"""}" ) -> {"id":"item_cloth_global_01","name":"紅色運動服","category":"equipment","type":"cloth","source":"global","rarity":"common","texture":"cloth_red_sport","icon":"icon_cloth_red_sport","placeable":"&IF($I28,"true","false")&","effects":[{"type":"rewardRate","value":"&TEXT($K28,"0.##")&"},{"type":"none","value":"&TEXT($M28,"0.##")&"}],"unlockType":"shop","desc":"大人帶幼兒園的運動服"}
A29: item_fullset_global_01 | B29: 五迷服 | C29: equipment | D29: fullset | E29: global | F29: common | G29: fullset_fan | H29: icon_fullset_fan | I29: FALSE | J29: rewardRate | K29: 0.1 | L29: dropRate | M29: 0.05 | N29: 0.1 | O29: 0.05 | P29: 0 | Q29: event | R29: 五月大的小粉絲 | S29: 測試中 | U29: TRUE | V29: 28 | W29: global_028 | X29: =IF($A29="","","{""id"":"""&$A29&""",""name"":"""&$B29&""",""category"":"""&$C29&""",""type"":"""&$D29&""",""source"":"""&$E29&""",""rarity"":"""&$F29&""",""texture"":"""&$G29&""",""icon"":"""&$H29&""",""placeable"":""&IF($I29,""true"",""false"")&"",""effects"":[{""type"":"""&$J29&""",""value"":""&TEXT($K29,""0.##"")&""},{""type"":"""&$L29&""",""value"":""&TEXT($M29,""0.##"")&""}],""unlockType"":"""&$Q29&""",""desc"":"""&$R29&"""}" ) -> {"id":"item_fullset_global_01","name":"五迷服","category":"equipment","type":"fullset","source":"global","rarity":"common","texture":"fullset_fan","icon":"icon_fullset_fan","placeable":"&IF($I29,"true","false")&","effects":[{"type":"rewardRate","value":"&TEXT($K29,"0.##")&"},{"type":"dropRate","value":"&TEXT($M29,"0.##")&"}],"unlockType":"event","desc":"五月大的小粉絲"}
A30: item_tool_global_01 | B30: 幸運吊飾 | C30: tool | D30: tool | E30: global | F30: rare | G30: tool_charm | H30: icon_charm | I30: FALSE | J30: chestRate | K30: 0.08 | L30: none | M30: 0 | N30: 0 | O30: 0 | P30: 0 | Q30: shop | R30: 掛在背包上會帶來好運 | S30: 測試中 | U30: TRUE | V30: 29 | W30: global_029 | X30: =IF($A30="","","{""id"":"""&$A30&""",""name"":"""&$B30&""",""category"":"""&$C30&""",""type"":"""&$D30&""",""source"":"""&$E30&""",""rarity"":"""&$F30&""",""texture"":"""&$G30&""",""icon"":"""&$H30&""",""placeable"":""&IF($I30,""true"",""false"")&"",""effects"":[{""type"":"""&$J30&""",""value"":""&TEXT($K30,""0.##"")&""},{""type"":"""&$L30&""",""value"":""&TEXT($M30,""0.##"")&""}],""unlockType"":"""&$Q30&""",""desc"":"""&$R30&"""}" ) -> {"id":"item_tool_global_01","name":"幸運吊飾","category":"tool","type":"tool","source":"global","rarity":"rare","texture":"tool_charm","icon":"icon_charm","placeable":"&IF($I30,"true","false")&","effects":[{"type":"chestRate","value":"&TEXT($K30,"0.##")&"},{"type":"none","value":"&TEXT($M30,"0.##")&"}],"unlockType":"shop","desc":"掛在背包上會帶來好運"}
A31: item_fullset_secret_guard | B31: 母上的守護 | C31: equipment | D31: fullset | E31: secret | F31: legend | G31: fullset_guard | H31: icon_guard | I31: FALSE | J31: freeEntry | K31: 1 | L31: freeStageEntry | M31: 1 | N31: 0 | O31: 0 | P31: 0 | Q31: secret | R31: 感受到了母親大人的愛意 | S31: 測試中 | T31: 彩蛋裝備：5秒內依序點擊愛心→水晶→聲望 | U31: TRUE | V31: 30 | W31: secret_030 | X31: =IF($A31="","","{""id"":"""&$A31&""",""name"":"""&$B31&""",""category"":"""&$C31&""",""type"":"""&$D31&""",""source"":"""&$E31&""",""rarity"":"""&$F31&""",""texture"":"""&$G31&""",""icon"":"""&$H31&""",""placeable"":""&IF($I31,""true"",""false"")&"",""effects"":[{""type"":"""&$J31&""",""value"":""&TEXT($K31,""0.##"")&""},{""type"":"""&$L31&""",""value"":""&TEXT($M31,""0.##"")&""}],""unlockType"":"""&$Q31&""",""desc"":"""&$R31&"""}" ) -> {"id":"item_fullset_secret_guard","name":"母上的守護","category":"equipment","type":"fullset","source":"secret","rarity":"legend","texture":"fullset_guard","icon":"icon_guard","placeable":"&IF($I31,"true","false")&","effects":[{"type":"freeEntry","value":"&TEXT($K31,"0.##")&"},{"type":"freeStageEntry","value":"&TEXT($M31,"0.##")&"}],"unlockType":"secret","desc":"感受到了母親大人的愛意"}

Sheet export_ready
A1: id | B1: name | C1: type | D1: source | E1: rarity | F1: texture | G1: icon | H1: placeable | I1: effect1_type | J1: effect1_value | K1: effect2_type | L1: effect2_value | M1: unlockType | N1: desc | O1: gameKey | P1: sortOrder
A2: =IF(equipment_master!$U2=FALSE,"",equipment_master!$A2) -> item_hat_daily_01 | B2: =IF($A2="","",equipment_master!$B2) -> 小髮夾 | C2: =IF($A2="","",equipment_master!$D2) -> hat | D2: =IF($A2="","",equipment_master!$E2) -> starter | E2: =IF($A2="","",equipment_master!$F2) -> common | F2: =IF($A2="","",equipment_master!$G2) -> item_hat_daily_01 | G2: =IF($A2="","",equipment_master!$H2) -> item_hat_daily_01 | H2: =IF($A2="","",equipment_master!$I2) -> FALSE | I2: =IF($A2="","",equipment_master!$J2) -> none | J2: =IF($A2="","",equipment_master!$K2) -> 0 | K2: =IF($A2="","",equipment_master!$L2) -> none | L2: =IF($A2="","",equipment_master!$M2) -> 0 | M2: =IF($A2="","",equipment_master!$Q2) -> starter | N2: =IF($A2="","",equipment_master!$R2) -> 簡單可愛的小髮夾 | O2: =IF($A2="","",equipment_master!$W2) -> starter_001 | P2: =IF($A2="","",equipment_master!$V2) -> 1
A3: =IF(equipment_master!$U3=FALSE,"",equipment_master!$A3) -> item_cloth_daily_01 | B3: =IF($A3="","",equipment_master!$B3) -> 休閒裝 | C3: =IF($A3="","",equipment_master!$D3) -> cloth | D3: =IF($A3="","",equipment_master!$E3) -> starter | E3: =IF($A3="","",equipment_master!$F3) -> common | F3: =IF($A3="","",equipment_master!$G3) -> item_cloth_daily_01 | G3: =IF($A3="","",equipment_master!$H3) -> item_cloth_daily_01 | H3: =IF($A3="","",equipment_master!$I3) -> FALSE | I3: =IF($A3="","",equipment_master!$J3) -> rewardRate | J3: =IF($A3="","",equipment_master!$K3) -> 0.05 | K3: =IF($A3="","",equipment_master!$L3) -> none | L3: =IF($A3="","",equipment_master!$M3) -> 0 | M3: =IF($A3="","",equipment_master!$Q3) -> starter | N3: =IF($A3="","",equipment_master!$R3) -> 舒適的日常衣服 | O3: =IF($A3="","",equipment_master!$W3) -> starter_002 | P3: =IF($A3="","",equipment_master!$V3) -> 2
A4: =IF(equipment_master!$U4=FALSE,"",equipment_master!$A4) -> item_hat_common_tiara | B4: =IF($A4="","",equipment_master!$B4) -> 小皇冠 | C4: =IF($A4="","",equipment_master!$D4) -> hat | D4: =IF($A4="","",equipment_master!$E4) -> global | E4: =IF($A4="","",equipment_master!$F4) -> rare | F4: =IF($A4="","",equipment_master!$G4) -> hat_tiara | G4: =IF($A4="","",equipment_master!$H4) -> icon_hat_tiara | H4: =IF($A4="","",equipment_master!$I4) -> FALSE | I4: =IF($A4="","",equipment_master!$J4) -> rewardRate | J4: =IF($A4="","",equipment_master!$K4) -> 0.2 | K4: =IF($A4="","",equipment_master!$L4) -> none | L4: =IF($A4="","",equipment_master!$M4) -> 0 | M4: =IF($A4="","",equipment_master!$Q4) -> drop | N4: =IF($A4="","",equipment_master!$R4) -> 一頂閃亮的小皇冠 | O4: =IF($A4="","",equipment_master!$W4) -> global_003 | P4: =IF($A4="","",equipment_master!$V4) -> 3
A5: =IF(equipment_master!$U5=FALSE,"",equipment_master!$A5) -> item_cloth_common_fairy | B5: =IF($A5="","",equipment_master!$B5) -> 小仙子洋裝 | C5: =IF($A5="","",equipment_master!$D5) -> cloth | D5: =IF($A5="","",equipment_master!$E5) -> firefly | E5: =IF($A5="","",equipment_master!$F5) -> rare | F5: =IF($A5="","",equipment_master!$G5) -> cloth_fairy | G5: =IF($A5="","",equipment_master!$H5) -> icon_cloth_fairy | H5: =IF($A5="","",equipment_master!$I5) -> FALSE | I5: =IF($A5="","",equipment_master!$J5) -> dropRate | J5: =IF($A5="","",equipment_master!$K5) -> 0.15 | K5: =IF($A5="","",equipment_master!$L5) -> none | L5: =IF($A5="","",equipment_master!$M5) -> 0 | M5: =IF($A5="","",equipment_master!$Q5) -> drop | N5: =IF($A5="","",equipment_master!$R5) -> 輕盈可愛的小仙子洋裝 | O5: =IF($A5="","",equipment_master!$W5) -> firefly_004 | P5: =IF($A5="","",equipment_master!$V5) -> 4
A6: =IF(equipment_master!$U6=FALSE,"",equipment_master!$A6) -> item_fullset_pink_home_01 | B6: =IF($A6="","",equipment_master!$B6) -> 粉色居家服 | C6: =IF($A6="","",equipment_master!$D6) -> fullset | D6: =IF($A6="","",equipment_master!$E6) -> starter | E6: =IF($A6="","",equipment_master!$F6) -> common | F6: =IF($A6="","",equipment_master!$G6) -> fullset_pink_home_01 | G6: =IF($A6="","",equipment_master!$H6) -> icon_fullset_pink_home_01 | H6: =IF($A6="","",equipment_master!$I6) -> FALSE | I6: =IF($A6="","",equipment_master!$J6) -> rewardRate | J6: =IF($A6="","",equipment_master!$K6) -> 0.1 | K6: =IF($A6="","",equipment_master!$L6) -> dropRate | L6: =IF($A6="","",equipment_master!$M6) -> 0.05 | M6: =IF($A6="","",equipment_master!$Q6) -> starter | N6: =IF($A6="","",equipment_master!$R6) -> 舒服又可愛的粉色居家服 | O6: =IF($A6="","",equipment_master!$W6) -> starter_005 | P6: =IF($A6="","",equipment_master!$V6) -> 5
A7: =IF(equipment_master!$U7=FALSE,"",equipment_master!$A7) -> item_hat_explore_01 | B7: =IF($A7="","",equipment_master!$B7) -> 探險遮陽帽 | C7: =IF($A7="","",equipment_master!$D7) -> hat | D7: =IF($A7="","",equipment_master!$E7) -> treasure | E7: =IF($A7="","",equipment_master!$F7) -> rare | F7: =IF($A7="","",equipment_master!$G7) -> hat_explorer | G7: =IF($A7="","",equipment_master!$H7) -> icon_hat_explorer | H7: =IF($A7="","",equipment_master!$I7) -> FALSE | I7: =IF($A7="","",equipment_master!$J7) -> extraPlayCount | J7: =IF($A7="","",equipment_master!$K7) -> 1 | K7: =IF($A7="","",equipment_master!$L7) -> none | L7: =IF($A7="","",equipment_master!$M7) -> 0 | M7: =IF($A7="","",equipment_master!$Q7) -> drop | N7: =IF($A7="","",equipment_master!$R7) -> 探險時能多一次嘗試機會 | O7: =IF($A7="","",equipment_master!$W7) -> treasure_006 | P7: =IF($A7="","",equipment_master!$V7) -> 6
A8: =IF(equipment_master!$U8=FALSE,"",equipment_master!$A8) -> item_cloth_explore_01 | B8: =IF($A8="","",equipment_master!$B8) -> 多口袋背心 | C8: =IF($A8="","",equipment_master!$D8) -> cloth | D8: =IF($A8="","",equipment_master!$E8) -> treasure | E8: =IF($A8="","",equipment_master!$F8) -> rare | F8: =IF($A8="","",equipment_master!$G8) -> cloth_explorer | G8: =IF($A8="","",equipment_master!$H8) -> icon_cloth_explorer | H8: =IF($A8="","",equipment_master!$I8) -> FALSE | I8: =IF($A8="","",equipment_master!$J8) -> dropRate | J8: =IF($A8="","",equipment_master!$K8) -> 0.1 | K8: =IF($A8="","",equipment_master!$L8) -> none | L8: =IF($A8="","",equipment_master!$M8) -> 0 | M8: =IF($A8="","",equipment_master!$Q8) -> drop | N8: =IF($A8="","",equipment_master!$R8) -> 身上掛滿各種探險口袋 | O8: =IF($A8="","",equipment_master!$W8) -> treasure_007 | P8: =IF($A8="","",equipment_master!$V8) -> 7
A9: =IF(equipment_master!$U9=FALSE,"",equipment_master!$A9) -> item_fullset_explore_01 | B9: =IF($A9="","",equipment_master!$B9) -> 野外小偵查 | C9: =IF($A9="","",equipment_master!$D9) -> fullset | D9: =IF($A9="","",equipment_master!$E9) -> treasure | E9: =IF($A9="","",equipment_master!$F9) -> rare | F9: =IF($A9="","",equipment_master!$G9) -> fullset_explorer | G9: =IF($A9="","",equipment_master!$H9) -> icon_fullset_explorer | H9: =IF($A9="","",equipment_master!$I9) -> FALSE | I9: =IF($A9="","",equipment_master!$J9) -> revealHint | J9: =IF($A9="","",equipment_master!$K9) -> 1 | K9: =IF($A9="","",equipment_master!$L9) -> none | L9: =IF($A9="","",equipment_master!$M9) -> 0 | M9: =IF($A9="","",equipment_master!$Q9) -> drop | N9: =IF($A9="","",equipment_master!$R9) -> 一件充滿探險味道的衣服 | O9: =IF($A9="","",equipment_master!$W9) -> treasure_008 | P9: =IF($A9="","",equipment_master!$V9) -> 8
A10: =IF(equipment_master!$U10=FALSE,"",equipment_master!$A10) -> item_tool_explore_01 | B10: =IF($A10="","",equipment_master!$B10) -> 高能放大鏡 | C10: =IF($A10="","",equipment_master!$D10) -> tool | D10: =IF($A10="","",equipment_master!$E10) -> treasure | E10: =IF($A10="","",equipment_master!$F10) -> rare | F10: =IF($A10="","",equipment_master!$G10) -> tool_magnifier | G10: =IF($A10="","",equipment_master!$H10) -> icon_magnifier | H10: =IF($A10="","",equipment_master!$I10) -> FALSE | I10: =IF($A10="","",equipment_master!$J10) -> rareDropRate | J10: =IF($A10="","",equipment_master!$K10) -> 0.05 | K10: =IF($A10="","",equipment_master!$L10) -> none | L10: =IF($A10="","",equipment_master!$M10) -> 0 | M10: =IF($A10="","",equipment_master!$Q10) -> drop | N10: =IF($A10="","",equipment_master!$R10) -> 讓寶藏的細節變得更明顯 | O10: =IF($A10="","",equipment_master!$W10) -> treasure_009 | P10: =IF($A10="","",equipment_master!$V10) -> 9
A11: =IF(equipment_master!$U11=FALSE,"",equipment_master!$A11) -> item_hat_firefly_01 | B11: =IF($A11="","",equipment_master!$B11) -> 螢光小帽 | C11: =IF($A11="","",equipment_master!$D11) -> hat | D11: =IF($A11="","",equipment_master!$E11) -> firefly | E11: =IF($A11="","",equipment_master!$F11) -> rare | F11: =IF($A11="","",equipment_master!$G11) -> hat_firefly | G11: =IF($A11="","",equipment_master!$H11) -> icon_hat_firefly | H11: =IF($A11="","",equipment_master!$I11) -> FALSE | I11: =IF($A11="","",equipment_master!$J11) -> timeBonus | J11: =IF($A11="","",equipment_master!$K11) -> 3 | K11: =IF($A11="","",equipment_master!$L11) -> none | L11: =IF($A11="","",equipment_master!$M11) -> 0 | M11: =IF($A11="","",equipment_master!$Q11) -> drop | N11: =IF($A11="","",equipment_master!$R11) -> 夜晚的螢光會停留得更久 | O11: =IF($A11="","",equipment_master!$W11) -> firefly_010 | P11: =IF($A11="","",equipment_master!$V11) -> 10
A12: =IF(equipment_master!$U12=FALSE,"",equipment_master!$A12) -> item_cloth_firefly_01 | B12: =IF($A12="","",equipment_master!$B12) -> 發光小背心 | C12: =IF($A12="","",equipment_master!$D12) -> cloth | D12: =IF($A12="","",equipment_master!$E12) -> firefly | E12: =IF($A12="","",equipment_master!$F12) -> rare | F12: =IF($A12="","",equipment_master!$G12) -> cloth_firefly | G12: =IF($A12="","",equipment_master!$H12) -> icon_cloth_firefly | H12: =IF($A12="","",equipment_master!$I12) -> FALSE | I12: =IF($A12="","",equipment_master!$J12) -> rewardRate | J12: =IF($A12="","",equipment_master!$K12) -> 0.15 | K12: =IF($A12="","",equipment_master!$L12) -> none | L12: =IF($A12="","",equipment_master!$M12) -> 0 | M12: =IF($A12="","",equipment_master!$Q12) -> drop | N12: =IF($A12="","",equipment_master!$R12) -> 微微發光的小背心 | O12: =IF($A12="","",equipment_master!$W12) -> firefly_011 | P12: =IF($A12="","",equipment_master!$V12) -> 11
A13: =IF(equipment_master!$U13=FALSE,"",equipment_master!$A13) -> item_fullset_firefly_01 | B13: =IF($A13="","",equipment_master!$B13) -> 森林精靈服 | C13: =IF($A13="","",equipment_master!$D13) -> fullset | D13: =IF($A13="","",equipment_master!$E13) -> firefly | E13: =IF($A13="","",equipment_master!$F13) -> rare | F13: =IF($A13="","",equipment_master!$G13) -> fullset_firefly | G13: =IF($A13="","",equipment_master!$H13) -> icon_fullset_firefly | H13: =IF($A13="","",equipment_master!$I13) -> FALSE | I13: =IF($A13="","",equipment_master!$J13) -> extraMistake | J13: =IF($A13="","",equipment_master!$K13) -> 1 | K13: =IF($A13="","",equipment_master!$L13) -> none | L13: =IF($A13="","",equipment_master!$M13) -> 0 | M13: =IF($A13="","",equipment_master!$Q13) -> drop | N13: =IF($A13="","",equipment_master!$R13) -> 帶有森林魔法的精靈服 | O13: =IF($A13="","",equipment_master!$W13) -> firefly_012 | P13: =IF($A13="","",equipment_master!$V13) -> 12
... A31: =IF(equipment_master!$U31=FALSE,"",equipment_master!$A31) -> item_fullset_secret_guard | B31: =IF($A31="","",equipment_master!$B31) -> 母上的守護 | C31: =IF($A31="","",equipment_master!$D31) -> fullset | D31: =IF($A31="","",equipment_master!$E31) -> secret | E31: =IF($A31="","",equipment_master!$F31) -> legend | F31: =IF($A31="","",equipment_master!$G31) -> fullset_guard | G31: =IF($A31="","",equipment_master!$H31) -> icon_guard | H31: =IF($A31="","",equipment_master!$I31) -> FALSE | I31: =IF($A31="","",equipment_master!$J31) -> freeEntry | J31: =IF($A31="","",equipment_master!$K31) -> 1 | K31: =IF($A31="","",equipment_master!$L31) -> freeStageEntry | L31: =IF($A31="","",equipment_master!$M31) -> 1 | M31: =IF($A31="","",equipment_master!$Q31) -> secret | N31: =IF($A31="","",equipment_master!$R31) -> 感受到了母親大人的愛意 | O31: =IF($A31="","",equipment_master!$W31) -> secret_030 | P31: =IF($A31="","",equipment_master!$V31) -> 30

Sheet 工作表1
A1: 《最終 ITEM_DB 稀有度 / source 命名規則表》，之後你整個《森林益智樂園 / BushExplore》都可以照這套走。
A3: 這版目標是：
A5: 好懂
A7: 不容易打架
A9: 方便你之後擴充
A11: 符合你現在的寶箱 / 彩蛋 / 關卡限定設計
A15: ITEM_DB 最終規則：先分成 3 個層次看
A17: 1. id
A19: 物品唯一編號
A21: 2. rarity
A23: 物品稀有度 / 顯示等級
A25: 3. source
... A508: rarity 用途表
A510: rarity | B510: 中文建議 | C510: 是否進正式寶箱池
A511: common | B511: 普通 | C511: 可
A512: rare | B512: 稀有 | C512: 可
A513: stage | B513: 關卡限定 | C513: 可，但限對應遊戲
A514: dream | B514: 夢幻 | C514: 可，主要夢幻寶箱
A515: myth | B515: 神話 | C515: 可，極低機率
A516: legendary | B516: 傳說 / 特殊收藏 | C516: 原則上不作正式池主體
A519: source 用途表
A521: source | B521: 用途 | C521: 是否進一般抽獎池
A522: global | B522: 全域共通 | C522: 可
A523: bush | B523: 草叢尋寶 | C523: 可
A524: campfire | B524: 營火 | C524: 可
A525: firefly | B525: 螢火蟲 | C525: 可
A526: animals | B526: 動物玩法 | C526: 可
A527: constellation | B527: 星座玩法 | C527: 可
A528: special | B528: 特殊事件 | C528: 視你程式控制
A529: secret | B529: 彩蛋取得 | C529: 不可
A532: 七、你之後寫 ITEM_DB 的一句話規則
A534: 最穩公式
A536: rarity 管顯示與稀有度，source 管來源與是否進池。
A540: 八、我幫你做最後定稿建議
A542: 你之後就照這個原則走：
A544: 正式抽獎主稀有度
A546: common / rare / stage / dream / myth
A548: 特殊彩蛋顯示稀有度
A550: legendary
A552: 不進一般池的控制
...

Sheet field_map
A1: 欄位 | B1: 說明 | C1: 遊戲端建議型別
A2: id | B2: 唯一識別碼 | C2: string
A3: name | B3: 顯示名稱 | C3: string
A4: type | B4: 裝備類型 hat/cloth/fullset/tool | C4: string
A5: source | B5: 來源玩法或來源池 | C5: string
A6: rarity | B6: 稀有度 | C6: string
A7: texture | B7: 角色貼圖 key | C7: string
A8: icon | B8: UI 圖示 key | C8: string
A9: placeable | B9: 是否可放置 | C9: bool
A10: effect1_type / effect2_type | B10: 效果類型 | C10: string
A11: effect1_value / effect2_value | B11: 效果數值 | C11: number
A12: unlockType | B12: 解鎖方式 | C12: string
... A15: json_preview | B15: 每列 JSON 預覽，可給工程當參考 | C15: string
